2023-07-24 21:28:37,832 DEBUG core.py Error in auth, data:
Traceback (most recent call last):
  File "/home/dilbazi/async_cat/async/lesson3/server/core.py", line 283, in autorize_user
    ans = get_message(sock)
  File "/home/dilbazi/async_cat/async/lesson3/common/decorator.py", line 36, in log_saver
    ret = func_to_log(*args, **kwargs)
  File "/home/dilbazi/async_cat/async/lesson3/common/utils.py", line 11, in get_message
    encoded_response = client.recv(MAX_PACKAGE_LENGTH)
socket.timeout: timed out
